<?xml version="1.0" encoding="utf-8"?>
<!-- This URDF was automatically created by SolidWorks to URDF Exporter! Originally created by Stephen Brawner (brawner@gmail.com) 
     Commit Version: 1.6.0-4-g7f85cfe  Build Version: 1.6.7995.38578
     For more information, please see http://wiki.ros.org/sw_urdf_exporter -->
<robot xmlns:xacro="http://www.ros.org/wiki/xacro" >

  <link name="base_footprint" />
  
  <joint name="base_footprint_joint" type="fixed">
    <parent link="base_footprint"/>
    <child link="base_link"/>
    <origin xyz="0.0 0.0 0.0"/>
  </joint>

  <link name="base_link">
    <inertial>
      <origin xyz="0.0055548 -1.0842E-17 0.12396" rpy="0 0 0" />
      <mass value="4" />
      <inertia ixx="0.034878" ixy="0" ixz="-0.00014227" iyy="0.030104" iyz="0" izz="0.019095" /> 
    </inertial>
    <visual>
      <origin xyz="0 0 0" rpy="0 0 0" />
      <geometry>
        <mesh filename="file:$(find bbr_robot)/meshes/base_link.STL" />
      </geometry>
      <material name="white">
        <color rgba="1 1 1 1" />
      </material>
    </visual>
    <collision>
      <origin xyz="0 0 0" rpy="0 0 0" />
      <geometry>
        <mesh filename="file:$(find bbr_robot)/meshes/base_link.STL" />
      </geometry>
    </collision>
  </link>
  
  <link name="IMU_link">
    <inertial>
      <origin xyz="-4.6593E-05 -4.3368E-18 0.019093" rpy="0 0 0" />
      <mass value="0.037898" />
      <inertia ixx="6.4173E-06" ixy="-4.749E-23" ixz="1.601E-09" iyy="6.456E-06" iyz="3.2231E-22" izz="7.9599E-06" />
    </inertial>
    <visual>
      <origin xyz="0 0 0" rpy="0 0 0" />
      <geometry>
        <mesh filename="file:$(find bbr_robot)/meshes/IMU_link.STL" />
      </geometry>
      <material name="white">
        <color rgba="1 1 1 1" />
      </material>
    </visual>
    <collision>
      <origin xyz="0 0 0" rpy="0 0 0" />
      <geometry>
        <mesh filename="file:$(find bbr_robot)/meshes/IMU_link.STL" />
      </geometry>
    </collision>
  </link>
  
  <joint name="IMU_joint" type="fixed">
    <origin xyz="0 0 0.27" rpy="0 0 0" />
    <parent link="base_link" />
    <child link="IMU_link" />
    <axis xyz="0 0 0" />
  </joint>
  
  <link name="camera_link">
    <inertial>
      <origin xyz="-0.00052746 0.00012148 0.024642" rpy="0 0 0" />
      <mass value="0.17291" />
      <inertia ixx="0.00033064" ixy="-2.2114E-07" ixz="3.2623E-08" iyy="3.6772E-05" iyz="-7.5136E-09" izz="0.00033873" />
    </inertial>
    <visual>
      <origin xyz="0 0 0" rpy="0 0 0" />
      <geometry>
        <mesh filename="file:$(find bbr_robot)/meshes/camera_link.STL" />
      </geometry>
      <material name="white">
        <color rgba="1 1 1 1" />
      </material>
    </visual>
    <collision>
      <origin xyz="0 0 0" rpy="0 0 0" />
      <geometry>
        <mesh filename="file:$(find bbr_robot)/meshes/camera_link.STL" />
      </geometry>
    </collision>
  </link>
  
  <joint name="camera_joint" type="fixed">
    <origin xyz="0 0 0.03" rpy="0 0 0" />
    <parent link="IMU_link" />
    <child link="camera_link" />
    <axis xyz="0 0 0" />
  </joint>
  
  <link name="right_shoulder_link">
    <inertial>
      <origin xyz="-0.0001526 -0.015 0.010932" rpy="0 0 0" />
      <mass value="0.12398" />
      <inertia ixx="6.4232E-05" ixy="-1.6665E-20" ixz="3.4019E-07" iyy="8.4873E-05" iyz="-2.8292E-20" izz="3.9866E-05" />
    </inertial>
    <visual>
      <origin xyz="0 0 0" rpy="0 0 0" />
      <geometry>
        <mesh filename="file:$(find bbr_robot)/meshes/right_shoulder_link.STL" />
      </geometry>
      <material name="white">
        <color rgba="1 1 1 1" />
      </material>
    </visual>
    <collision>
      <origin xyz="0 0 0" rpy="0 0 0" />
      <geometry>
        <mesh filename="file:$(find bbr_robot)/meshes/right_shoulder_link.STL" />
      </geometry>
    </collision>
  </link>
 
  <joint name="right_shoulder_joint" type="revolute">
    <origin xyz="0 -0.11 0.22" rpy="0 0 0" />
    <parent link="base_link" />
    <child link="right_shoulder_link" />
    <axis xyz="0 1 0" />
    <limit lower="-3.14" upper="3.14" effort="100" velocity="100" />
  </joint>
 
  <link name="right_limb_link">
    <inertial>
      <origin xyz="0.23812 0.0074497 0.02755" rpy="0 0 0" />
      <mass value="0.32057" />
      <inertia ixx="4.986E-05" ixy="-0.00023219" ixz="-0.00016738" iyy="0.0075326" iyz="-5.2112E-06" izz="0.0075201" />
    </inertial>
    <visual>
      <origin xyz="0 0 0" rpy="0 0 0" />
      <geometry>
        <mesh filename="file:$(find bbr_robot)/meshes/right_limb_link.STL" />
      </geometry>
      <material name="white">
        <color rgba="1 1 1 1" />
      </material>
    </visual>
    <collision>
      <origin xyz="0 0 0" rpy="0 0 0" />
      <geometry>
        <mesh filename="file:$(find bbr_robot)/meshes/right_limb_link.STL" />
      </geometry>
    </collision>
  </link>
 
  <joint name="right_limb_joint" type="revolute">
    <origin xyz="0 -0.015 0.049995" rpy="0 0 0" />
    <parent link="right_shoulder_link" />
    <child link="right_limb_link" />
    <axis xyz="-0.013958 0 0.9999" />
    <limit lower="-3.14" upper="3.14" effort="100" velocity="100" />
  </joint>
 
  <link name="left_shoulder_link">
    <inertial>
      <origin xyz="-0.00016452 0.015 0.010932" rpy="0 0 0" />
      <mass value="0.12398" />
      <inertia ixx="6.4231E-05" ixy="2.1973E-22" ixz="3.6674E-07" iyy="8.4873E-05" iyz="2.5622E-20" izz="3.9867E-05" />
    </inertial>
    <visual>
      <origin xyz="0 0 0" rpy="0 0 0" />
      <geometry>
        <mesh filename="file:$(find bbr_robot)/meshes/left_shoulder_link.STL" />
      </geometry>
      <material name="white">
        <color rgba="1 1 1 1" />
      </material>
    </visual>
    <collision>
      <origin xyz="0 0 0" rpy="0 0 0" />
      <geometry>
        <mesh filename="file:$(find bbr_robot)/meshes/left_shoulder_link.STL" />
      </geometry>
    </collision>
  </link>
 
  <joint name="left_shoulder_joint" type="revolute">
    <origin xyz="0 0.11 0.22" rpy="0 0 0" />
    <parent link="base_link" />
    <child link="left_shoulder_link" />
    <axis xyz="0 1 0" />
    <limit lower="-3.14" upper="3.14" effort="100" velocity="100" />
  </joint>
 
  <link name="left_limb_link">
    <inertial>
      <origin xyz="0.23814 -0.00578 0.02781" rpy="0 0 0" />
      <mass value="0.32057" />
      <inertia ixx="4.7528E-05" ixy="0.00018343" ixz="-0.00017558" iyy="0.0075353" iyz="4.2891E-06" izz="0.0075197" /> 
    </inertial>
    <visual>
      <origin xyz="0 0 0" rpy="0 0 0" />
      <geometry>
        <mesh filename="file:$(find bbr_robot)/meshes/left_limb_link.STL" />
      </geometry>
      <material name="white">
        <color rgba="1 1 1 1" />
      </material>
    </visual>
    <collision>
      <origin xyz="0 0 0" rpy="0 0 0" />
      <geometry>
        <mesh filename="file:$(find bbr_robot)/meshes/left_limb_link.STL" />
      </geometry>
    </collision>
  </link>
 
  <joint name="left_limb_joint" type="revolute">
    <origin xyz="0 0.015 0.049994" rpy="0 0 0" />
    <parent link="left_shoulder_link" />
    <child link="left_limb_link" />
    <axis xyz="-0.015048 0 0.99989" />
    <limit lower="-3.14" upper="3.14" effort="100" velocity="100" />
  </joint>
 
  <link name="right_wheel_link"> 
    <inertial>
      <origin xyz="9.541E-18 -0.02063 -1.3878E-17" rpy="0 0 0" />
      <mass value="0.67292" />
      <inertia ixx="0.0012159" ixy="1.0596E-20" ixz="-3.5451E-37" iyy="0.0022611" iyz="-1.4966E-36" izz="0.0012159" />
    </inertial>
    <visual>
      <origin xyz="0 0 0" rpy="0 0 0" />
      <geometry>
        <mesh filename="file:$(find bbr_robot)/meshes/right_wheel_link.STL" />
      </geometry>
      <material
        name="white">
        <color rgba="1 1 1 1" />
      </material>
    </visual>
    <collision>
      <origin xyz="0 0 0" rpy="0 0 0" />
      <geometry>
        <mesh filename="file:$(find bbr_robot)/meshes/right_wheel_link.STL" />
      </geometry>
    </collision>
  </link>
 
  <joint name="right_wheel_joint" type="continuous">
    <origin xyz="0 -0.12 0.05" rpy="0 0 0" />
    <parent link="base_link" />
    <child link="right_wheel_link" />
    <axis xyz="0 1 0" />
  </joint>
 
  <link name="left_wheel_link">
    <inertial>
      <origin xyz="8.6736E-19 0.02063 -1.3878E-17" rpy="0 0 0" />
      <mass value="0.67292" />
      <inertia ixx="0.0012159" ixy="9.6665E-21" ixz="3.5451E-37" iyy="0.0022611" iyz="1.4966E-36" izz="0.0012159" />
    </inertial>
    <visual>
      <origin xyz="0 0 0" rpy="0 0 0" />
      <geometry>
        <mesh filename="file:$(find bbr_robot)/meshes/left_wheel_link.STL" />
      </geometry>
      <material
        name="white">
        <color rgba="1 1 1 1" />
      </material>
    </visual>
    <collision>
      <origin xyz="0 0 0" rpy="0 0 0" />
      <geometry>
        <mesh filename="file:$(find bbr_robot)/meshes/left_wheel_link.STL" />
      </geometry>
    </collision>
  </link>
 
  <joint name="left_wheel_joint" type="continuous">
    <origin xyz="0 0.12 0.05" rpy="0 0 0" />
    <parent link="base_link" />
    <child link="left_wheel_link" />
    <axis xyz="0 1 0" />
  </joint>
 
  <link name="front_caster_link">
    <inertial>
      <origin xyz="2.7756E-17 -6.9389E-18 -0.01125" rpy="0 0 0" />
      <mass value="0.5" />
      <inertia ixx="0.00011672" ixy="0" ixz="0" iyy="0.00011672" iyz="0" izz="0.00018" />
    </inertial>
    <visual>
      <origin xyz="0 0 0" rpy="0 0 0" />
      <geometry>
        <mesh filename="file:$(find bbr_robot)/meshes/front_caster_link.STL" />
      </geometry>
      <material
        name="white">
        <color rgba="1 1 1 1" />
      </material>
    </visual>
    <collision>
      <origin xyz="0 0 0" rpy="0 0 0" />
      <geometry>
        <mesh filename="file:$(find bbr_robot)/meshes/front_caster_link.STL" />
      </geometry>
    </collision>
  </link>
 
  <joint name="front_caster_joint" type="fixed">
    <origin xyz="0.12144 0 0" rpy="0 0 0" />
    <parent link="base_link" />
    <child link="front_caster_link" />
    <axis xyz="0 0 0" />
  </joint>
 
  <link name="rear_caster_link">
    <inertial>
      <origin xyz="-2.7756E-17 6.9389E-18 -0.011093" rpy="0 0 0" />
      <mass value="0.5" />
      <inertia ixx="0.00011672" ixy="0" ixz="0" iyy="0.00011672" iyz="0" izz="0.00018" />
    </inertial>
    <visual>
      <origin xyz="0 0 0" rpy="0 0 0" />
      <geometry>
        <mesh filename="file:$(find bbr_robot)/meshes/rear_caster_link.STL" />
      </geometry>
      <material
        name="white">
        <color rgba="1 1 1 1" />
      </material>
    </visual>
    <collision>
      <origin xyz="0 0 0" rpy="0 0 0" />
      <geometry>
        <mesh filename="file:$(find bbr_robot)/meshes/rear_caster_link.STL" />
      </geometry>
    </collision>
  </link>
 
  <joint name="rear_caster_joint" type="fixed">
    <origin xyz="-0.10856 0 0" rpy="0 0 0" />
    <parent link="base_link" />
    <child link="rear_caster_link" />
    <axis xyz="0 0 0" />
  </joint>
  
</robot>